Workbook
Name NativeTimeline_Order_Date: #N/A
Name Slicer_Country: #N/A
Name Slicer_Product: #N/A

Sheet Top_Items
A3: Row Labels | B3: Sum of Sales | D3: Row Labels | E3: Sum of Quantity
A4: Laptop | B4: 213041.96 | D4: Desk | E4: 290
A5: Smartphone | B5: 119707.05 | D5: Laptop | E5: 260
A6: Desk | B6: 89391.41 | D6: Keyboard | E6: 255
A7: Monitor | B7: 47402.13 | D7: Mouse | E7: 254
A8: Printer | B8: 45684.25 | D8: Notebook | E8: 248
A9: Grand Total | B9: 515226.8 | D9: Grand Total | E9: 1307

Sheet Raw_Data
A1: Order_ID | B1: Order_Date | C1: Customer_ID | D1: Country | E1: Region | F1: Product | G1: Category | H1: Quantity | I1: Unit_Price | J1: Discount | K1: Sales | L1: Payment_Method
A2: ORD-0557 | B2: 45658 | C2: CUST-0044 | D2: Ghana | E2: West Africa | F2: Office Chair | G2: Furniture | H2: 6 | I2: 222.25 | J2: 0.1 | K2: 1200.15 | L2: Bank Transfer
A3: ORD-0385 | B3: 45658 | C3: CUST-0143 | D3: United Kingdom | E3: Europe | F3: Monitor | G3: Electronics | H3: 6 | I3: 270.86 | J3: 0.15 | K3: 1381.39 | L3: Bank Transfer
A4: ORD-0510 | B4: 45659 | C4: CUST-0178 | D4: Kenya | E4: East Africa | F4: Desk Lamp | G4: Furniture | H4: 2 | I4: 55.08 | J4: 0 | K4: 110.16 | L4: Card
A5: ORD-0218 | B5: 45662 | C5: CUST-0086 | D5: South Africa | E5: Southern Africa | F5: Smartphone | G5: Electronics | H5: 5 | I5: 597.21 | J5: 0.15 | K5: 2538.14 | L5: Mobile Money
A6: ORD-0562 | B6: 45663 | C6: CUST-0147 | D6: Nigeria | E6: West Africa | F6: Smartphone | G6: Electronics | H6: 7 | I6: 590.39 | J6: 0.15 | K6: 3512.82 | L6: Mobile Money
A7: ORD-0263 | B7: 45664 | C7: CUST-0155 | D7: Kenya | E7: East Africa | F7: Monitor | G7: Electronics | H7: 2 | I7: 277.84 | J7: 0.2 | K7: 444.54 | L7: Mobile Money
A8: ORD-0089 | B8: 45665 | C8: CUST-0132 | D8: South Africa | E8: Southern Africa | F8: Notebook | G8: Office Supplies | H8: 3 | I8: 15.11 | J8: 0.1 | K8: 40.8 | L8: Mobile Money
A9: ORD-0530 | B9: 45665 | C9: CUST-0029 | D9: United States | E9: North America | F9: Printer | G9: Office Supplies | H9: 3 | I9: 254.64 | J9: 0.05 | K9: 725.72 | L9: Card
A10: ORD-0187 | B10: 45665 | C10: CUST-0079 | D10: Kenya | E10: East Africa | F10: Notebook | G10: Office Supplies | H10: 8 | I10: 13.98 | J10: 0.05 | K10: 106.25 | L10: Card
A11: ORD-0077 | B11: 45667 | C11: CUST-0056 | D11: Ghana | E11: West Africa | F11: Headphones | G11: Electronics | H11: 5 | I11: 130.57 | J11: 0.1 | K11: 587.56 | L11: Mobile Money
A12: ORD-0401 | B12: 45668 | C12: CUST-0017 | D12: Ghana | E12: West Africa | F12: Desk | G12: Furniture | H12: 5 | I12: 376.29 | J12: 0 | K12: 1881.45 | L12: Card
A13: ORD-0288 | B13: 45669 | C13: CUST-0014 | D13: Nigeria | E13: West Africa | F13: Mouse | G13: Electronics | H13: 4 | I13: 45.22 | J13: 0.2 | K13: 144.7 | L13: Bank Transfer
... A320: ORD-0180 | B320: 45867 | C320: CUST-0050 | D320: United Kingdom | E320: Europe | F320: Laptop | G320: Electronics | H320: 2 | I320: 895.24 | J320: 0 | K320: 1790.48 | L320: Card
A321: ORD-0565 | B321: 45867 | C321: CUST-0048 | D321: Nigeria | E321: West Africa | F321: Headphones | G321: Electronics | H321: 6 | J321: 0.1 | K321: 593.41 | L321: Card
A322: ORD-0346 | B322: 45867 | C322: CUST-0145 | D322: Kenya | E322: East Africa | F322: Mouse | G322: Electronics | H322: 1 | I322: 42.92 | J322: 0.1 | K322: 38.63 | L322: Bank Transfer
A323: ORD-0568 | B323: 45868 | C323: CUST-0067 | D323: Nigeria | E323: West Africa | F323: Backpack | G323: Accessories | H323: 2 | I323: 81.07 | J323: 0.15 | K323: 137.82 | L323: Card
A324: ORD-0201 | B324: 45868 | C324: CUST-0150 | D324: United States | E324: North America | F324: Desk | G324: Furniture | H324: 7 | I324: 318.06 | J324: 0 | K324: 2226.42 | L324: Card
A325: ORD-0076 | B325: 45869 | C325: CUST-0157 | D325: Ghana | E325: West Africa | F325: Mouse | G325: Electronics | H325: 4 | I325: 49.38 | J325: 0.15 | K325: 167.89 | L325: Mobile Money
A326: ORD-0473 | B326: 45869 | C326: CUST-0168 | D326: Ghana | E326: West Africa | F326: Keyboard | G326: Electronics | H326: 4 | I326: 81.81 | J326: 0.15 | K326: 278.15 | L326: Card
A327: ORD-0443 | B327: 45869 | C327: CUST-0003 | D327: Nigeria | E327: West Africa | F327: Mouse | G327: Electronics | H327: 2 | I327: 42.31 | J327: 0.05 | K327: 80.39 | L327: Card
A328: ORD-0563 | B328: 45871 | C328: CUST-0177 | D328: Ghana | E328: West Africa | F328: Desk Lamp | G328: Furniture | H328: 2 | I328: 56.32 | J328: 0.1 | K328: 101.38 | L328: Mobile Money
A329: ORD-0314 | B329: 45871 | C329: CUST-0143 | D329: Ghana | E329: West Africa | F329: Monitor | G329: Electronics | H329: 5 | I329: 279.88 | J329: 0.05 | K329: 1329.43 | L329: Bank Transfer
A330: ORD-0155 | B330: 45872 | C330: CUST-0082 | D330: United States | E330: North America | F330: Desk | G330: Furniture | H330: 7 | I330: 335.81 | J330: 0.25 | K330: 1763 | L330: Cash
A331: ORD-0507 | B331: 45872 | C331: CUST-0131 | D331: United Kingdom | E331: Europe | F331: Monitor | G331: Electronics | H331: 4 | I331: 281.7 | J331: 0.2 | K331: 901.44 | L331: Bank Transfer
A332: ORD-0390 | B332: 45872 | C332: CUST-0120 | D332: Ghana | E332: West Africa | F332: Keyboard | G332: Electronics | H332: 7 | I332: 75.38 | J332: 0.2 | K332: 422.13 | L332: Card
A333: ORD-0419 | B333: 45873 | C333: CUST-0057 | D333: Nigeria | E333: West Africa | F333: Desk Lamp | G333: Furniture | H333: 3 | I333: 52.36 | J333: 0.05 | K333: 149.23 | L333: Cash
... A412: ORD-0426 | B412: 45917 | C412: CUST-0108 | D412: Kenya | E412: East Africa | F412: Smartphone | G412: Electronics | H412: 3 | I412: 607.89 | J412: 0.05 | K412: 1732.49 | L412: Card
A413: ORD-0164 | B413: 45917 | C413: CUST-0059 | D413: United States | E413: North America | F413: Keyboard | G413: Electronics | H413: 3 | I413: 86.46 | J413: 0.3 | K413: 181.57
A414: ORD-0209 | B414: 45918 | C414: CUST-0168 | D414: Ghana | E414: West Africa | F414: Laptop | G414: Electronics | H414: 3 | I414: 866.19 | J414: 0.1 | K414: 2338.71 | L414: Bank Transfer
A415: ORD-0117 | B415: 45918 | C415: CUST-0157 | D415: Kenya | E415: East Africa | F415: Office Chair | G415: Furniture | H415: 5 | I415: 203.61 | J415: 0.1 | K415: 916.25 | L415: Bank Transfer
A416: ORD-0173 | B416: 45919 | C416: CUST-0147 | D416: United Kingdom | E416: Europe | F416: Keyboard | G416: Electronics | H416: 8 | I416: 82.85 | J416: 0.1 | K416: 596.52 | L416: Card
A417: ORD-0582 | B417: 45919 | C417: CUST-0163 | D417: Nigeria | E417: West Africa | F417: Printer | G417: Office Supplies | H417: 5 | I417: 229.23 | J417: 0.1 | K417: 1031.53 | L417: Mobile Money
A418: ORD-0319 | B418: 45920 | C418: CUST-0080 | D418: United Kingdom | E418: Europe | F418: Keyboard | G418: Electronics | H418: 2 | I418: 74.53 | J418: 0.15 | K418: 126.7 | L418: Bank Transfer
A419: ORD-0028 | B419: 45920 | C419: CUST-0144 | D419: South Africa | E419: Southern Africa | F419: Mouse | G419: Electronics | H419: 1 | I419: 42.38 | J419: 0.1 | K419: 38.14 | L419: Mobile Money
A420: ORD-0477 | B420: 45921 | C420: CUST-0179 | D420: United Kingdom | E420: Europe | F420: Headphones | G420: Electronics | H420: 2 | I420: 120.33 | J420: 0.05 | K420: 228.63 | L420: Cash
A421: ORD-0042 | B421: 45921 | C421: CUST-0144 | D421: South Africa | E421: Southern Africa | F421: Desk Lamp | G421: Furniture | H421: 2 | I421: 49.56 | J421: 0.15 | K421: 84.25 | L421: Card
A422: ORD-0384 | B422: 45921 | C422: CUST-0026 | D422: Nigeria | E422: West Africa | F422: Keyboard | G422: Electronics | H422: 6 | I422: 87.32 | J422: 0 | K422: 523.92 | L422: Cash
A423: ORD-0533 | B423: 45921 | C423: CUST-0095 | D423: United States | E423: North America | F423: Office Chair | G423: Furniture | H423: 5 | I423: 237.48 | J423: 0.15 | K423: 1009.29 | L423: Cash
A424: ORD-0152 | B424: 45921 | C424: CUST-0149 | D424: United States | E424: North America | F424: Monitor | G424: Electronics | H424: 1 | I424: 281.11 | J424: 0.1 | K424: 253 | L424: Bank Transfer
...

Sheet Graphs
B2: Row Labels | C2: Total Sales | J2: Row Labels | K2: Sum of Sales | S2: Row Labels | T2: Sum of Sales
B3: 0-0.1 | C3: 261572.33 | J3: Accessories | K3: 15498.76 | S3: Backpack | T3: 15498.76
B4: 0.1-0.2 | C4: 238609.9 | J4: Electronics | K4: 428836.37 | S4: Desk | T4: 89391.41
B5: 0.2-0.3 | C5: 110470.35 | J5: Furniture | K5: 139730.42 | S5: Desk Lamp | T5: 9859.81
B6: 0.3-0.4 | C6: 22242.85 | J6: Office Supplies | K6: 49068.82 | S6: Headphones | T6: 20077.22
B7: 0.4-0.5 | C7: 238.94 | J7: Grand Total | K7: 633134.37 | S7: Keyboard | T7: 18372.99
B8: Grand Total | C8: 633134.37 | S8: Laptop | T8: 213041.96
S9: Monitor | T9: 47402.13
S10: Mouse | T10: 10235.02
S11: Notebook | T11: 3384.57
S12: Office Chair | T12: 40479.2
S13: Printer | T13: 45684.25
D14: Row Labels | E14: Sum of Sales | S14: Smartphone | T14: 119707.05
D15: East Africa | E15: 89362.26 | S15: Grand Total | T15: 633134.37
D16: Kenya | E16: 89362.26
D17: Europe | E17: 97654.69
D18: United Kingdom | E18: 97654.69
D19: North America | E19: 89176.93
D20: United States | E20: 89176.93
D21: Southern Africa | E21: 88607.2
D22: South Africa | E22: 88607.2
D23: West Africa | E23: 268333.29
D24: Ghana | E24: 128138.97
D25: Nigeria | E25: 140194.32
D26: Grand Total | E26: 633134.37

Sheet Cleaned_data
A1: Order_ID | B1: Order_Date | C1: Customer_ID | D1: Country | E1: Region | F1: Product | G1: Category | H1: Quantity | I1: Unit_Price | J1: Discount | K1: Sales | L1: Payment_Method
A2: =TRIM(Raw_Data_Copy!A2) -> ORD-0557 | B2: 45658 | C2: =TRIM(Raw_Data_Copy!C2) -> CUST-0044 | D2: =PROPER(TRIM(Raw_Data_Copy!D2)) -> Ghana | E2: =PROPER(TRIM(Raw_Data_Copy!E2)) -> West Africa | F2: =PROPER(TRIM(Raw_Data_Copy!F2)) -> Office Chair | G2: =PROPER(TRIM(Raw_Data_Copy!G2)) -> Furniture | H2: =TRIM(Raw_Data_Copy!H2) -> 6 | I2: =TRIM(Raw_Data_Copy!I2) -> 222.25 | J2: =TRIM(Raw_Data_Copy!J2) -> 0.1 | K2: =ROUND(Cleaned_data!$H2*Cleaned_data!$I2*(1-Cleaned_data!$J2),2) -> 1200.15 | L2: =PROPER(TRIM(Raw_Data_Copy!L2)) -> Bank Transfer
A3: =TRIM(Raw_Data_Copy!A3) -> ORD-0385 | B3: 45658 | C3: =TRIM(Raw_Data_Copy!C3) -> CUST-0143 | D3: =PROPER(TRIM(Raw_Data_Copy!D3)) -> United Kingdom | E3: =PROPER(TRIM(Raw_Data_Copy!E3)) -> Europe | F3: =PROPER(TRIM(Raw_Data_Copy!F3)) -> Monitor | G3: =PROPER(TRIM(Raw_Data_Copy!G3)) -> Electronics | H3: =TRIM(Raw_Data_Copy!H3) -> 6 | I3: =TRIM(Raw_Data_Copy!I3) -> 270.86 | J3: =TRIM(Raw_Data_Copy!J3) -> 0.15 | K3: =ROUND(Cleaned_data!$H3*Cleaned_data!$I3*(1-Cleaned_data!$J3),2) -> 1381.39 | L3: =PROPER(TRIM(Raw_Data_Copy!L3)) -> Bank Transfer
A4: =TRIM(Raw_Data_Copy!A4) -> ORD-0510 | B4: 45659 | C4: =TRIM(Raw_Data_Copy!C4) -> CUST-0178 | D4: =PROPER(TRIM(Raw_Data_Copy!D4)) -> Kenya | E4: =PROPER(TRIM(Raw_Data_Copy!E4)) -> East Africa | F4: =PROPER(TRIM(Raw_Data_Copy!F4)) -> Desk Lamp | G4: =PROPER(TRIM(Raw_Data_Copy!G4)) -> Furniture | H4: =TRIM(Raw_Data_Copy!H4) -> 2 | I4: =TRIM(Raw_Data_Copy!I4) -> 55.08 | J4: =TRIM(Raw_Data_Copy!J4) -> 0 | K4: =ROUND(Cleaned_data!$H4*Cleaned_data!$I4*(1-Cleaned_data!$J4),2) -> 110.16 | L4: =PROPER(TRIM(Raw_Data_Copy!L4)) -> Card
A5: =TRIM(Raw_Data_Copy!A5) -> ORD-0218 | B5: 45662 | C5: =TRIM(Raw_Data_Copy!C5) -> CUST-0086 | D5: =PROPER(TRIM(Raw_Data_Copy!D5)) -> South Africa | E5: =PROPER(TRIM(Raw_Data_Copy!E5)) -> Southern Africa | F5: =PROPER(TRIM(Raw_Data_Copy!F5)) -> Smartphone | G5: =PROPER(TRIM(Raw_Data_Copy!G5)) -> Electronics | H5: =TRIM(Raw_Data_Copy!H5) -> 5 | I5: =TRIM(Raw_Data_Copy!I5) -> 597.21 | J5: =TRIM(Raw_Data_Copy!J5) -> 0.15 | K5: =ROUND(Cleaned_data!$H5*Cleaned_data!$I5*(1-Cleaned_data!$J5),2) -> 2538.14 | L5: =PROPER(TRIM(Raw_Data_Copy!L5)) -> Mobile Money
A6: =TRIM(Raw_Data_Copy!A6) -> ORD-0562 | B6: 45663 | C6: =TRIM(Raw_Data_Copy!C6) -> CUST-0147 | D6: =PROPER(TRIM(Raw_Data_Copy!D6)) -> Nigeria | E6: =PROPER(TRIM(Raw_Data_Copy!E6)) -> West Africa | F6: =PROPER(TRIM(Raw_Data_Copy!F6)) -> Smartphone | G6: =PROPER(TRIM(Raw_Data_Copy!G6)) -> Electronics | H6: =TRIM(Raw_Data_Copy!H6) -> 7 | I6: =TRIM(Raw_Data_Copy!I6) -> 590.39 | J6: =TRIM(Raw_Data_Copy!J6) -> 0.15 | K6: =ROUND(Cleaned_data!$H6*Cleaned_data!$I6*(1-Cleaned_data!$J6),2) -> 3512.82 | L6: =PROPER(TRIM(Raw_Data_Copy!L6)) -> Mobile Money
A7: =TRIM(Raw_Data_Copy!A7) -> ORD-0263 | B7: 45664 | C7: =TRIM(Raw_Data_Copy!C7) -> CUST-0155 | D7: =PROPER(TRIM(Raw_Data_Copy!D7)) -> Kenya | E7: =PROPER(TRIM(Raw_Data_Copy!E7)) -> East Africa | F7: =PROPER(TRIM(Raw_Data_Copy!F7)) -> Monitor | G7: =PROPER(TRIM(Raw_Data_Copy!G7)) -> Electronics | H7: =TRIM(Raw_Data_Copy!H7) -> 2 | I7: =TRIM(Raw_Data_Copy!I7) -> 277.84 | J7: =TRIM(Raw_Data_Copy!J7) -> 0.2 | K7: =ROUND(Cleaned_data!$H7*Cleaned_data!$I7*(1-Cleaned_data!$J7),2) -> 444.54 | L7: =PROPER(TRIM(Raw_Data_Copy!L7)) -> Mobile Money
A8: =TRIM(Raw_Data_Copy!A8) -> ORD-0089 | B8: 45665 | C8: =TRIM(Raw_Data_Copy!C8) -> CUST-0132 | D8: =PROPER(TRIM(Raw_Data_Copy!D8)) -> South Africa | E8: =PROPER(TRIM(Raw_Data_Copy!E8)) -> Southern Africa | F8: =PROPER(TRIM(Raw_Data_Copy!F8)) -> Notebook | G8: =PROPER(TRIM(Raw_Data_Copy!G8)) -> Office Supplies | H8: =TRIM(Raw_Data_Copy!H8) -> 3 | I8: =TRIM(Raw_Data_Copy!I8) -> 15.11 | J8: =TRIM(Raw_Data_Copy!J8) -> 0.1 | K8: =ROUND(Cleaned_data!$H8*Cleaned_data!$I8*(1-Cleaned_data!$J8),2) -> 40.8 | L8: =PROPER(TRIM(Raw_Data_Copy!L8)) -> Mobile Money
A9: =TRIM(Raw_Data_Copy!A9) -> ORD-0530 | B9: 45665 | C9: =TRIM(Raw_Data_Copy!C9) -> CUST-0029 | D9: =PROPER(TRIM(Raw_Data_Copy!D9)) -> United States | E9: =PROPER(TRIM(Raw_Data_Copy!E9)) -> North America | F9: =PROPER(TRIM(Raw_Data_Copy!F9)) -> Printer | G9: =PROPER(TRIM(Raw_Data_Copy!G9)) -> Office Supplies | H9: =TRIM(Raw_Data_Copy!H9) -> 3 | I9: =TRIM(Raw_Data_Copy!I9) -> 254.64 | J9: =TRIM(Raw_Data_Copy!J9) -> 0.05 | K9: =ROUND(Cleaned_data!$H9*Cleaned_data!$I9*(1-Cleaned_data!$J9),2) -> 725.72 | L9: =PROPER(TRIM(Raw_Data_Copy!L9)) -> Card
A10: =TRIM(Raw_Data_Copy!A10) -> ORD-0187 | B10: 45665 | C10: =TRIM(Raw_Data_Copy!C10) -> CUST-0079 | D10: =PROPER(TRIM(Raw_Data_Copy!D10)) -> Kenya | E10: =PROPER(TRIM(Raw_Data_Copy!E10)) -> East Africa | F10: =PROPER(TRIM(Raw_Data_Copy!F10)) -> Notebook | G10: =PROPER(TRIM(Raw_Data_Copy!G10)) -> Office Supplies | H10: =TRIM(Raw_Data_Copy!H10) -> 8 | I10: =TRIM(Raw_Data_Copy!I10) -> 13.98 | J10: =TRIM(Raw_Data_Copy!J10) -> 0.05 | K10: =ROUND(Cleaned_data!$H10*Cleaned_data!$I10*(1-Cleaned_data!$J10),2) -> 106.25 | L10: =PROPER(TRIM(Raw_Data_Copy!L10)) -> Card
A11: =TRIM(Raw_Data_Copy!A11) -> ORD-0077 | B11: 45667 | C11: =TRIM(Raw_Data_Copy!C11) -> CUST-0056 | D11: =PROPER(TRIM(Raw_Data_Copy!D11)) -> Ghana | E11: =PROPER(TRIM(Raw_Data_Copy!E11)) -> West Africa | F11: =PROPER(TRIM(Raw_Data_Copy!F11)) -> Headphones | G11: =PROPER(TRIM(Raw_Data_Copy!G11)) -> Electronics | H11: =TRIM(Raw_Data_Copy!H11) -> 5 | I11: =TRIM(Raw_Data_Copy!I11) -> 130.57 | J11: =TRIM(Raw_Data_Copy!J11) -> 0.1 | K11: =ROUND(Cleaned_data!$H11*Cleaned_data!$I11*(1-Cleaned_data!$J11),2) -> 587.57 | L11: =PROPER(TRIM(Raw_Data_Copy!L11)) -> Mobile Money
A12: =TRIM(Raw_Data_Copy!A12) -> ORD-0401 | B12: 45668 | C12: =TRIM(Raw_Data_Copy!C12) -> CUST-0017 | D12: =PROPER(TRIM(Raw_Data_Copy!D12)) -> Ghana | E12: =PROPER(TRIM(Raw_Data_Copy!E12)) -> West Africa | F12: =PROPER(TRIM(Raw_Data_Copy!F12)) -> Desk | G12: =PROPER(TRIM(Raw_Data_Copy!G12)) -> Furniture | H12: =TRIM(Raw_Data_Copy!H12) -> 5 | I12: =TRIM(Raw_Data_Copy!I12) -> 376.29 | J12: =TRIM(Raw_Data_Copy!J12) -> 0 | K12: =ROUND(Cleaned_data!$H12*Cleaned_data!$I12*(1-Cleaned_data!$J12),2) -> 1881.45 | L12: =PROPER(TRIM(Raw_Data_Copy!L12)) -> Card
A13: =TRIM(Raw_Data_Copy!A13) -> ORD-0288 | B13: 45669 | C13: =TRIM(Raw_Data_Copy!C13) -> CUST-0014 | D13: =PROPER(TRIM(Raw_Data_Copy!D13)) -> Nigeria | E13: =PROPER(TRIM(Raw_Data_Copy!E13)) -> West Africa | F13: =PROPER(TRIM(Raw_Data_Copy!F13)) -> Mouse | G13: =PROPER(TRIM(Raw_Data_Copy!G13)) -> Electronics | H13: =TRIM(Raw_Data_Copy!H13) -> 4 | I13: =TRIM(Raw_Data_Copy!I13) -> 45.22 | J13: =TRIM(Raw_Data_Copy!J13) -> 0.2 | K13: =ROUND(Cleaned_data!$H13*Cleaned_data!$I13*(1-Cleaned_data!$J13),2) -> 144.7 | L13: =PROPER(TRIM(Raw_Data_Copy!L13)) -> Bank Transfer
... A601: =TRIM(Raw_Data_Copy!A601) -> ORD-0380 | B601: 46022 | C601: =TRIM(Raw_Data_Copy!C601) -> CUST-0163 | D601: =PROPER(TRIM(Raw_Data_Copy!D601)) -> United States | E601: =PROPER(TRIM(Raw_Data_Copy!E601)) -> North America | F601: =PROPER(TRIM(Raw_Data_Copy!F601)) -> Notebook | G601: =PROPER(TRIM(Raw_Data_Copy!G601)) -> Office Supplies | H601: =TRIM(Raw_Data_Copy!H601) -> 2 | I601: =TRIM(Raw_Data_Copy!I601) -> 14.83 | J601: =TRIM(Raw_Data_Copy!J601) -> 0.15 | K601: =ROUND(Cleaned_data!$H601*Cleaned_data!$I601*(1-Cleaned_data!$J601),2) -> 25.21 | L601: =PROPER(TRIM(Raw_Data_Copy!L601)) -> Mobile Money
A602: Total

Sheet Info
A1: INFO RECORED | G1: ANALYZE SALES BY CATEGORY
B2: Missing values | C2: Found 1 missing value in columns unit_price, sales and payment_method | J2: Percentage
B3: Dupicate rows of same items | C3: no duplicate of that sort found | H3: {=_xlfn.UNIQUE(Raw_Data_Copy!G2:G601)} -> Furniture | I3: =SUMIF(Raw_Data_Copy!$G$2:$G$601,"Furniture",Raw_Data_Copy!$N$2:$N$601) -> 141210.63 | J3: =SUM(I3)/SUM($I$3:$I$6) -> 0.22276572
B4: Strange and inconsistent dates | C4: no strange dates found | H4: Electronics | I4: =SUMIF(Raw_Data_Copy!$G$2:$G$601,H4,Raw_Data_Copy!$N$2:$N$601) -> 428119.22 | J4: =SUM(I4)/SUM($I$3:$I$6) -> 0.6753761
B5: Negative values and outliers | C5: no negative value and outliers found in the quantity column | H5: Office Supplies | I5: =SUMIF(Raw_Data_Copy!$G$2:$G$601,H5,Raw_Data_Copy!$N$2:$N$601) -> 49068.88 | J5: =SUM(I5)/SUM($I$3:$I$6) -> 0.077408225
B6: Errors in approximation | C6: 25 errors in Sales when approximating to 2 decimal places | H6: Accessories | I6: =SUMIF(Raw_Data_Copy!$G$2:$G$601,H6,Raw_Data_Copy!$N$2:$N$601) -> 15498.77 | J6: =SUM(I6)/SUM($I$3:$I$6) -> 0.024449962
H11: ANALYZE SALES BY COUNTRY
H12: {=_xlfn.UNIQUE(Cleaned_data!D2:D601)} -> Ghana | I12: =SUMIF(Raw_Data_Copy!D2:D601,Raw_Data_Copy!D2,Raw_Data_Copy!N2:N601) -> 128099.51 | J12: =SUM(I12)/SUM($I$12:$I$17) -> 0.20208237
H13: United Kingdom | I13: =SUMIF(Raw_Data_Copy!D3:D602,Raw_Data_Copy!D3,Raw_Data_Copy!N3:N602) -> 97654.71 | J13: =SUM(I13)/SUM($I$12:$I$17) -> 0.15405442
B14: CALCULATIONS | H14: Kenya | I14: =SUMIF(Raw_Data_Copy!D4:D603,Raw_Data_Copy!D4,Raw_Data_Copy!N4:N603) -> 89362.27 | J14: =SUM(I14)/SUM($I$12:$I$17) -> 0.14097274
B15: number of quantity | C15: =SUM(Raw_Data_Copy!H2:H601) -> 2743 | H15: South Africa | I15: =SUMIF(Raw_Data_Copy!D5:D604,Raw_Data_Copy!D5,Raw_Data_Copy!N5:N604) -> 88607.26 | J15: =SUM(I15)/SUM($I$12:$I$17) -> 0.13978168
B16: number of sales(revenue) | C16: =SUM(Raw_Data_Copy!N2:N601) -> 633897.5 | H16: Nigeria | I16: =SUMIF(Raw_Data_Copy!D6:D605,Raw_Data_Copy!D6,Raw_Data_Copy!N6:N605) -> 139516.62 | J16: =SUM(I16)/SUM($I$12:$I$17) -> 0.22009334
B17: order counts | C17: =COUNTA(Raw_Data_Copy!A2:A601) -> 600 | H17: United States | I17: =SUMIF(Raw_Data_Copy!D7:D606,H17,Raw_Data_Copy!N7:N606) -> 90657.13 | J17: =SUM(I17)/SUM($I$12:$I$17) -> 0.14301544
B18: average order value | C18: =C16/C17 -> 1056.4958
B19: average unit price | C19: =AVERAGE(Raw_Data_Copy!I2:I601) -> 250.90042

Sheet Missing_values
C1: missing_value_count
B2: Order_ID | C2: =COUNTIF(Raw_Data!A2:A601,"") -> 0
B3: Order_Date | C3: =COUNTIF(Raw_Data!B2:B601,"") -> 0
B4: Customer_ID | C4: =COUNTIF(Raw_Data!C2:C601,"") -> 0
B5: Country | C5: =COUNTIF(Raw_Data!D2:D601,"") -> 0
B6: Region | C6: =COUNTBLANK(Raw_Data!E2:E601) -> 0
B7: Product | C7: =COUNTBLANK(Raw_Data!F2:F601) -> 0
B8: Category | C8: =COUNTBLANK(Raw_Data!G2:G601) -> 0
B9: Quantity | C9: =COUNTBLANK(Raw_Data!H2:H601) -> 0
B10: Unit_Price | C10: =COUNTBLANK(Raw_Data!I2:I601) -> 1
B11: Discount | C11: =COUNTBLANK(Raw_Data_Copy!J2:J601) -> 0
B12: Sales | C12: =COUNTBLANK(Raw_Data!K2:K601) -> 1
B13: Payment_Method | C13: =COUNTBLANK(Raw_Data!L2:L601) -> 1

Sheet Monthly_Sales_counts
A3: months | B3: Count of Order_ID
A4: Jan | B4: 49
A5: Feb | B5: 33
A6: Mar | B6: 47
A7: Apr | B7: 55
A8: May | B8: 44
A9: Jun | B9: 49
A10: Jul | B10: 49
A11: Aug | B11: 53
A12: Sep | B12: 57
A13: Oct | B13: 56
A14: Nov | B14: 53
A15: Dec | B15: 55
A16: Grand Total | B16: 600

Sheet Raw_Data_Copy
A1: Order_ID | B1: Order_Date | C1: Customer_ID | D1: Country | E1: Region | F1: Product | G1: Category | H1: Quantity | I1: Unit_Price | J1: Discount | K1: Sales | L1: Payment_Method | R1: date
A2: ORD-0557 | B2: 45658 | C2: CUST-0044 | D2: Ghana | E2: West Africa | F2: Office Chair | G2: Furniture | H2: 6 | I2: 222.25 | J2: 0.1 | K2: 1200.15 | L2: Bank Transfer | N2: =ROUND(H2*I2*(1-J2),2) -> 1200.15 | O2: =H2*I2*(1-J2) -> 1200.15 | P2: =IF(ROUND(O2,2)=ROUND(K2,2),"Same","Different") -> Same | R2: =MIN(B2:B601) -> 45658 | S2: =IF(OR(B2<DATE(2025,1,1),B2>DATE(2025,12,31)),"Strange", "Okay") -> Okay
A3: ORD-0385 | B3: 45658 | C3: CUST-0143 | D3: United Kingdom | E3: Europe | F3: Monitor | G3: Electronics | H3: 6 | I3: 270.86 | J3: 0.15 | K3: 1381.39 | L3: Bank Transfer | N3: =ROUND(H3*I3*(1-J3),2) -> 1381.39 | O3: =H3*I3*(1-J3) -> 1381.386 | P3: =IF(ROUND(O3,2)=ROUND(K3,2),"Same","Different") -> Same | R3: =MAX(B2:B601) -> 46022 | S3: =IF(OR(B3<DATE(2025,1,1),B3>DATE(2025,12,31)),"Strange", "Okay") -> Okay
A4: ORD-0510 | B4: 45659 | C4: CUST-0178 | D4: Kenya | E4: East Africa | F4: Desk Lamp | G4: Furniture | H4: 2 | I4: 55.08 | J4: 0 | K4: 110.16 | L4: Card | N4: =ROUND(H4*I4*(1-J4),2) -> 110.16 | O4: =H4*I4*(1-J4) -> 110.16 | P4: =IF(ROUND(O4,2)=ROUND(K4,2),"Same","Different") -> Same | S4: =IF(OR(B4<DATE(2025,1,1),B4>DATE(2025,12,31)),"Strange", "Okay") -> Okay
A5: ORD-0218 | B5: 45662 | C5: CUST-0086 | D5: South Africa | E5: Southern Africa | F5: Smartphone | G5: Electronics | H5: 5 | I5: 597.21 | J5: 0.15 | K5: 2538.14 | L5: Mobile Money | N5: =ROUND(H5*I5*(1-J5),2) -> 2538.14 | O5: =H5*I5*(1-J5) -> 2538.1425 | P5: =IF(ROUND(O5,2)=ROUND(K5,2),"Same","Different") -> Same | R5: =COUNTIF(S2:S601,"Strange") -> 0 | S5: =IF(OR(B5<DATE(2025,1,1),B5>DATE(2025,12,31)),"Strange", "Okay") -> Okay
A6: ORD-0562 | B6: 45663 | C6: CUST-0147 | D6: Nigeria | E6: West Africa | F6: Smartphone | G6: Electronics | H6: 7 | I6: 590.39 | J6: 0.15 | K6: 3512.82 | L6: Mobile Money | N6: =ROUND(H6*I6*(1-J6),2) -> 3512.82 | O6: =H6*I6*(1-J6) -> 3512.8205 | P6: =IF(ROUND(O6,2)=ROUND(K6,2),"Same","Different") -> Same | R6: =COUNTIFS(H2:H601,H2<1,H2:H601,H2>10) -> 0 | S6: =IF(OR(B6<DATE(2025,1,1),B6>DATE(2025,12,31)),"Strange", "Okay") -> Okay
A7: ORD-0263 | B7: 45664 | C7: CUST-0155 | D7: Kenya | E7: East Africa | F7: Monitor | G7: Electronics | H7: 2 | I7: 277.84 | J7: 0.2 | K7: 444.54 | L7: Mobile Money | N7: =ROUND(H7*I7*(1-J7),2) -> 444.54 | O7: =H7*I7*(1-J7) -> 444.544 | P7: =IF(ROUND(O7,2)=ROUND(K7,2),"Same","Different") -> Same | R7: =MEDIAN(H2:H601) -> 5 | S7: =IF(OR(B7<DATE(2025,1,1),B7>DATE(2025,12,31)),"Strange", "Okay") -> Okay
A8: ORD-0089 | B8: 45665 | C8: CUST-0132 | D8: South Africa | E8: Southern Africa | F8: Notebook | G8: Office Supplies | H8: 3 | I8: 15.11 | J8: 0.1 | K8: 40.8 | L8: Mobile Money | N8: =ROUND(H8*I8*(1-J8),2) -> 40.8 | O8: =H8*I8*(1-J8) -> 40.797 | P8: =IF(ROUND(O8,2)=ROUND(K8,2),"Same","Different") -> Same | R8: =AVERAGE(H2:H601) -> 4.5716667 | S8: =IF(OR(B8<DATE(2025,1,1),B8>DATE(2025,12,31)),"Strange", "Okay") -> Okay
A9: ORD-0530 | B9: 45665 | C9: CUST-0029 | D9: United States | E9: North America | F9: Printer | G9: Office Supplies | H9: 3 | I9: 254.64 | J9: 0.05 | K9: 725.72 | L9: Card | N9: =ROUND(H9*I9*(1-J9),2) -> 725.72 | O9: =H9*I9*(1-J9) -> 725.724 | P9: =IF(ROUND(O9,2)=ROUND(K9,2),"Same","Different") -> Same | R9: =COUNTIF(P2:P601,"Different") -> 25 | S9: =IF(OR(B9<DATE(2025,1,1),B9>DATE(2025,12,31)),"Strange", "Okay") -> Okay
A10: ORD-0187 | B10: 45665 | C10: CUST-0079 | D10: Kenya | E10: East Africa | F10: Notebook | G10: Office Supplies | H10: 8 | I10: 13.98 | J10: 0.05 | K10: 106.25 | L10: Card | N10: =ROUND(H10*I10*(1-J10),2) -> 106.25 | O10: =H10*I10*(1-J10) -> 106.248 | P10: =IF(ROUND(O10,2)=ROUND(K10,2),"Same","Different") -> Same | S10: =IF(OR(B10<DATE(2025,1,1),B10>DATE(2025,12,31)),"Strange", "Okay") -> Okay
A11: ORD-0077 | B11: 45667 | C11: CUST-0056 | D11: Ghana | E11: West Africa | F11: Headphones | G11: Electronics | H11: 5 | I11: 130.57 | J11: 0.1 | K11: 587.56 | L11: Mobile Money | N11: =ROUND(H11*I11*(1-J11),2) -> 587.57 | O11: =H11*I11*(1-J11) -> 587.565 | P11: =IF(ROUND(O11,2)=ROUND(K11,2),"Same","Different") -> Different | S11: =IF(OR(B11<DATE(2025,1,1),B11>DATE(2025,12,31)),"Strange", "Okay") -> Okay
A12: ORD-0401 | B12: 45668 | C12: CUST-0017 | D12: Ghana | E12: West Africa | F12: Desk | G12: Furniture | H12: 5 | I12: 376.29 | J12: 0 | K12: 1881.45 | L12: Card | N12: =ROUND(H12*I12*(1-J12),2) -> 1881.45 | O12: =H12*I12*(1-J12) -> 1881.45 | P12: =IF(ROUND(O12,2)=ROUND(K12,2),"Same","Different") -> Same | S12: =IF(OR(B12<DATE(2025,1,1),B12>DATE(2025,12,31)),"Strange", "Okay") -> Okay
A13: ORD-0288 | B13: 45669 | C13: CUST-0014 | D13: Nigeria | E13: West Africa | F13: Mouse | G13: Electronics | H13: 4 | I13: 45.22 | J13: 0.2 | K13: 144.7 | L13: Bank Transfer | N13: =ROUND(H13*I13*(1-J13),2) -> 144.7 | O13: =H13*I13*(1-J13) -> 144.704 | P13: =IF(ROUND(O13,2)=ROUND(K13,2),"Same","Different") -> Same | S13: =IF(OR(B13<DATE(2025,1,1),B13>DATE(2025,12,31)),"Strange", "Okay") -> Okay
A14: ORD-0257 | B14: 45669 | C14: CUST-0032 | D14: Nigeria | E14: West Africa | F14: Keyboard | G14: Electronics | H14: 5 | I14: 72.41 | J14: 0 | K14: 362.05 | L14: Cash | N14: =ROUND(H14*I14*(1-J14),2) -> 362.05 | O14: =H14*I14*(1-J14) -> 362.05 | P14: =IF(ROUND(O14,2)=ROUND(K14,2),"Same","Different") -> Same | S14: =IF(OR(B14<DATE(2025,1,1),B14>DATE(2025,12,31)),"Strange", "Okay") -> Okay
A15: ORD-0377 | B15: 45669 | C15: CUST-0070 | D15: United Kingdom | E15: Europe | F15: Monitor | G15: Electronics | H15: 4 | I15: 273.46 | J15: 0.15 | K15: 929.76 | L15: Mobile Money | N15: =ROUND(H15*I15*(1-J15),2) -> 929.76 | O15: =H15*I15*(1-J15) -> 929.764 | P15: =IF(ROUND(O15,2)=ROUND(K15,2),"Same","Different") -> Same | S15: =IF(OR(B15<DATE(2025,1,1),B15>DATE(2025,12,31)),"Strange", "Okay") -> Okay
A16: ORD-0543 | B16: 45670 | C16: CUST-0081 | D16: United States | E16: North America | F16: Laptop | G16: Electronics | H16: 7 | I16: 845.86 | J16: 0 | K16: 5921.02 | L16: Card | N16: =ROUND(H16*I16*(1-J16),2) -> 5921.02 | O16: =H16*I16*(1-J16) -> 5921.02 | P16: =IF(ROUND(O16,2)=ROUND(K16,2),"Same","Different") -> Same | S16: =IF(OR(B16<DATE(2025,1,1),B16>DATE(2025,12,31)),"Strange", "Okay") -> Okay
A17: ORD-0265 | B17: 45670 | C17: CUST-0082 | D17: Ghana | E17: West Africa | F17: Desk | G17: Furniture | H17: 2 | I17: 362.67 | J17: 0 | K17: 725.34 | L17: Mobile Money | N17: =ROUND(H17*I17*(1-J17),2) -> 725.34 | O17: =H17*I17*(1-J17) -> 725.34 | P17: =IF(ROUND(O17,2)=ROUND(K17,2),"Same","Different") -> Same | S17: =IF(OR(B17<DATE(2025,1,1),B17>DATE(2025,12,31)),"Strange", "Okay") -> Okay
A18: ORD-0551 | B18: 45670 | C18: CUST-0045 | D18: South Africa | E18: Southern Africa | F18: Mouse | G18: Electronics | H18: 7 | I18: 42.46 | J18: 0.2 | K18: 237.78 | L18: Card | N18: =ROUND(H18*I18*(1-J18),2) -> 237.78 | O18: =H18*I18*(1-J18) -> 237.776 | P18: =IF(ROUND(O18,2)=ROUND(K18,2),"Same","Different") -> Same | S18: =IF(OR(B18<DATE(2025,1,1),B18>DATE(2025,12,31)),"Strange", "Okay") -> Okay
A19: ORD-0538 | B19: 45670 | C19: CUST-0036 | D19: Ghana | E19: West Africa | F19: Keyboard | G19: Electronics | H19: 4 | I19: 85.23 | J19: 0.05 | K19: 323.87 | L19: card | N19: =ROUND(H19*I19*(1-J19),2) -> 323.87 | O19: =H19*I19*(1-J19) -> 323.874 | P19: =IF(ROUND(O19,2)=ROUND(K19,2),"Same","Different") -> Same | S19: =IF(OR(B19<DATE(2025,1,1),B19>DATE(2025,12,31)),"Strange", "Okay") -> Okay
A20: ORD-0095 | B20: 45671 | C20: CUST-0056 | D20: Kenya | E20: East Africa | F20: Printer | G20: Office Supplies | H20: 4 | I20: 243.45 | J20: 0.1 | K20: 876.42 | L20: Bank Transfer | N20: =ROUND(H20*I20*(1-J20),2) -> 876.42 | O20: =H20*I20*(1-J20) -> 876.42 | P20: =IF(ROUND(O20,2)=ROUND(K20,2),"Same","Different") -> Same | S20: =IF(OR(B20<DATE(2025,1,1),B20>DATE(2025,12,31)),"Strange", "Okay") -> Okay
A21: ORD-0393 | B21: 45671 | C21: CUST-0178 | D21: United States | E21: North America | F21: Printer | G21: Office Supplies | H21: 2 | I21: 266.07 | J21: 0.1 | K21: 478.93 | L21: Mobile Money | N21: =ROUND(H21*I21*(1-J21),2) -> 478.93 | O21: =H21*I21*(1-J21) -> 478.926 | P21: =IF(ROUND(O21,2)=ROUND(K21,2),"Same","Different") -> Same | S21: =IF(OR(B21<DATE(2025,1,1),B21>DATE(2025,12,31)),"Strange", "Okay") -> Okay
... A320: ORD-0180 | B320: 45867 | C320: CUST-0050 | D320: United Kingdom | E320: Europe | F320: Laptop | G320: Electronics | H320: 2 | I320: 895.24 | J320: 0 | K320: 1790.48 | L320: Card | N320: =ROUND(H320*I320*(1-J320),2) -> 1790.48 | O320: =H320*I320*(1-J320) -> 1790.48 | P320: =IF(ROUND(O320,2)=ROUND(K320,2),"Same","Different") -> Same | S320: =IF(OR(B320<DATE(2025,1,1),B320>DATE(2025,12,31)),"Strange", "Okay") -> Okay
A321: ORD-0565 | B321: 45867 | C321: CUST-0048 | D321: Nigeria | E321: West Africa | F321: Headphones | G321: Electronics | H321: 6 | J321: 0.1 | K321: 593.41 | L321: Card | N321: =ROUND(H321*I321*(1-J321),2) -> 0 | O321: =H321*I321*(1-J321) -> 0 | P321: =IF(ROUND(O321,2)=ROUND(K321,2),"Same","Different") -> Different | S321: =IF(OR(B321<DATE(2025,1,1),B321>DATE(2025,12,31)),"Strange", "Okay") -> Okay
A322: ORD-0346 | B322: 45867 | C322: CUST-0145 | D322: Kenya | E322: East Africa | F322: Mouse | G322: Electronics | H322: 1 | I322: 42.92 | J322: 0.1 | K322: 38.63 | L322: Bank Transfer | N322: =ROUND(H322*I322*(1-J322),2) -> 38.63 | O322: =H322*I322*(1-J322) -> 38.628 | P322: =IF(ROUND(O322,2)=ROUND(K322,2),"Same","Different") -> Same | S322: =IF(OR(B322<DATE(2025,1,1),B322>DATE(2025,12,31)),"Strange", "Okay") -> Okay
A323: ORD-0568 | B323: 45868 | C323: CUST-0067 | D323: Nigeria | E323: West Africa | F323: Backpack | G323: Accessories | H323: 2 | I323: 81.07 | J323: 0.15 | K323: 137.82 | L323: Card | N323: =ROUND(H323*I323*(1-J323),2) -> 137.82 | O323: =H323*I323*(1-J323) -> 137.819 | P323: =IF(ROUND(O323,2)=ROUND(K323,2),"Same","Different") -> Same | S323: =IF(OR(B323<DATE(2025,1,1),B323>DATE(2025,12,31)),"Strange", "Okay") -> Okay
A324: ORD-0201 | B324: 45868 | C324: CUST-0150 | D324: United States | E324: North America | F324: Desk | G324: Furniture | H324: 7 | I324: 318.06 | J324: 0 | K324: 2226.42 | L324: Card | N324: =ROUND(H324*I324*(1-J324),2) -> 2226.42 | O324: =H324*I324*(1-J324) -> 2226.42 | P324: =IF(ROUND(O324,2)=ROUND(K324,2),"Same","Different") -> Same | S324: =IF(OR(B324<DATE(2025,1,1),B324>DATE(2025,12,31)),"Strange", "Okay") -> Okay
A325: ORD-0076 | B325: 45869 | C325: CUST-0157 | D325: Ghana | E325: West Africa | F325: Mouse | G325: Electronics | H325: 4 | I325: 49.38 | J325: 0.15 | K325: 167.89 | L325: Mobile Money | N325: =ROUND(H325*I325*(1-J325),2) -> 167.89 | O325: =H325*I325*(1-J325) -> 167.892 | P325: =IF(ROUND(O325,2)=ROUND(K325,2),"Same","Different") -> Same | S325: =IF(OR(B325<DATE(2025,1,1),B325>DATE(2025,12,31)),"Strange", "Okay") -> Okay
A326: ORD-0473 | B326: 45869 | C326: CUST-0168 | D326: Ghana | E326: West Africa | F326: Keyboard | G326: Electronics | H326: 4 | I326: 81.81 | J326: 0.15 | K326: 278.15 | L326: Card | N326: =ROUND(H326*I326*(1-J326),2) -> 278.15 | O326: =H326*I326*(1-J326) -> 278.154 | P326: =IF(ROUND(O326,2)=ROUND(K326,2),"Same","Different") -> Same | S326: =IF(OR(B326<DATE(2025,1,1),B326>DATE(2025,12,31)),"Strange", "Okay") -> Okay
A327: ORD-0443 | B327: 45869 | C327: CUST-0003 | D327: Nigeria | E327: West Africa | F327: Mouse | G327: Electronics | H327: 2 | I327: 42.31 | J327: 0.05 | K327: 80.39 | L327: Card | N327: =ROUND(H327*I327*(1-J327),2) -> 80.39 | O327: =H327*I327*(1-J327) -> 80.389 | P327: =IF(ROUND(O327,2)=ROUND(K327,2),"Same","Different") -> Same | S327: =IF(OR(B327<DATE(2025,1,1),B327>DATE(2025,12,31)),"Strange", "Okay") -> Okay
A328: ORD-0563 | B328: 45871 | C328: CUST-0177 | D328: Ghana | E328: West Africa | F328: Desk Lamp | G328: Furniture | H328: 2 | I328: 56.32 | J328: 0.1 | K328: 101.38 | L328: Mobile Money | N328: =ROUND(H328*I328*(1-J328),2) -> 101.38 | O328: =H328*I328*(1-J328) -> 101.376 | P328: =IF(ROUND(O328,2)=ROUND(K328,2),"Same","Different") -> Same | S328: =IF(OR(B328<DATE(2025,1,1),B328>DATE(2025,12,31)),"Strange", "Okay") -> Okay
A329: ORD-0314 | B329: 45871 | C329: CUST-0143 | D329: Ghana | E329: West Africa | F329: Monitor | G329: Electronics | H329: 5 | I329: 279.88 | J329: 0.05 | K329: 1329.43 | L329: Bank Transfer | N329: =ROUND(H329*I329*(1-J329),2) -> 1329.43 | O329: =H329*I329*(1-J329) -> 1329.43 | P329: =IF(ROUND(O329,2)=ROUND(K329,2),"Same","Different") -> Same | S329: =IF(OR(B329<DATE(2025,1,1),B329>DATE(2025,12,31)),"Strange", "Okay") -> Okay
A330: ORD-0155 | B330: 45872 | C330: CUST-0082 | D330: United States | E330: North America | F330: Desk | G330: Furniture | H330: 7 | I330: 335.81 | J330: 0.25 | K330: 1763 | L330: Cash | N330: =ROUND(H330*I330*(1-J330),2) -> 1763 | O330: =H330*I330*(1-J330) -> 1763.0025 | P330: =IF(ROUND(O330,2)=ROUND(K330,2),"Same","Different") -> Same | S330: =IF(OR(B330<DATE(2025,1,1),B330>DATE(2025,12,31)),"Strange", "Okay") -> Okay
A331: ORD-0507 | B331: 45872 | C331: CUST-0131 | D331: United Kingdom | E331: Europe | F331: Monitor | G331: Electronics | H331: 4 | I331: 281.7 | J331: 0.2 | K331: 901.44 | L331: Bank Transfer | N331: =ROUND(H331*I331*(1-J331),2) -> 901.44 | O331: =H331*I331*(1-J331) -> 901.44 | P331: =IF(ROUND(O331,2)=ROUND(K331,2),"Same","Different") -> Same | S331: =IF(OR(B331<DATE(2025,1,1),B331>DATE(2025,12,31)),"Strange", "Okay") -> Okay
A332: ORD-0390 | B332: 45872 | C332: CUST-0120 | D332: Ghana | E332: West Africa | F332: Keyboard | G332: Electronics | H332: 7 | I332: 75.38 | J332: 0.2 | K332: 422.13 | L332: Card | N332: =ROUND(H332*I332*(1-J332),2) -> 422.13 | O332: =H332*I332*(1-J332) -> 422.128 | P332: =IF(ROUND(O332,2)=ROUND(K332,2),"Same","Different") -> Same | S332: =IF(OR(B332<DATE(2025,1,1),B332>DATE(2025,12,31)),"Strange", "Okay") -> Okay
A333: ORD-0419 | B333: 45873 | C333: CUST-0057 | D333: Nigeria | E333: West Africa | F333: Desk Lamp | G333: Furniture | H333: 3 | I333: 52.36 | J333: 0.05 | K333: 149.23 | L333: Cash | N333: =ROUND(H333*I333*(1-J333),2) -> 149.23 | O333: =H333*I333*(1-J333) -> 149.226 | P333: =IF(ROUND(O333,2)=ROUND(K333,2),"Same","Different") -> Same | S333: =IF(OR(B333<DATE(2025,1,1),B333>DATE(2025,12,31)),"Strange", "Okay") -> Okay
... A412: ORD-0426 | B412: 45917 | C412: CUST-0108 | D412: Kenya | E412: East Africa | F412: Smartphone | G412: Electronics | H412: 3 | I412: 607.89 | J412: 0.05 | K412: 1732.49 | L412: Card | N412: =ROUND(H412*I412*(1-J412),2) -> 1732.49 | O412: =H412*I412*(1-J412) -> 1732.4865 | P412: =IF(ROUND(O412,2)=ROUND(K412,2),"Same","Different") -> Same | S412: =IF(OR(B412<DATE(2025,1,1),B412>DATE(2025,12,31)),"Strange", "Okay") -> Okay
A413: ORD-0164 | B413: 45917 | C413: CUST-0059 | D413: United States | E413: North America | F413: Keyboard | G413: Electronics | H413: 3 | I413: 86.46 | J413: 0.3 | K413: 181.57 | N413: =ROUND(H413*I413*(1-J413),2) -> 181.57 | O413: =H413*I413*(1-J413) -> 181.566 | P413: =IF(ROUND(O413,2)=ROUND(K413,2),"Same","Different") -> Same | S413: =IF(OR(B413<DATE(2025,1,1),B413>DATE(2025,12,31)),"Strange", "Okay") -> Okay
A414: ORD-0209 | B414: 45918 | C414: CUST-0168 | D414: Ghana | E414: West Africa | F414: Laptop | G414: Electronics | H414: 3 | I414: 866.19 | J414: 0.1 | K414: 2338.71 | L414: Bank Transfer | N414: =ROUND(H414*I414*(1-J414),2) -> 2338.71 | O414: =H414*I414*(1-J414) -> 2338.713 | P414: =IF(ROUND(O414,2)=ROUND(K414,2),"Same","Different") -> Same | S414: =IF(OR(B414<DATE(2025,1,1),B414>DATE(2025,12,31)),"Strange", "Okay") -> Okay
A415: ORD-0117 | B415: 45918 | C415: CUST-0157 | D415: Kenya | E415: East Africa | F415: Office Chair | G415: Furniture | H415: 5 | I415: 203.61 | J415: 0.1 | K415: 916.25 | L415: Bank Transfer | N415: =ROUND(H415*I415*(1-J415),2) -> 916.25 | O415: =H415*I415*(1-J415) -> 916.245 | P415: =IF(ROUND(O415,2)=ROUND(K415,2),"Same","Different") -> Same | S415: =IF(OR(B415<DATE(2025,1,1),B415>DATE(2025,12,31)),"Strange", "Okay") -> Okay
A416: ORD-0173 | B416: 45919 | C416: CUST-0147 | D416: United Kingdom | E416: Europe | F416: Keyboard | G416: Electronics | H416: 8 | I416: 82.85 | J416: 0.1 | K416: 596.52 | L416: Card | N416: =ROUND(H416*I416*(1-J416),2) -> 596.52 | O416: =H416*I416*(1-J416) -> 596.52 | P416: =IF(ROUND(O416,2)=ROUND(K416,2),"Same","Different") -> Same | S416: =IF(OR(B416<DATE(2025,1,1),B416>DATE(2025,12,31)),"Strange", "Okay") -> Okay
...
